Workbook
Name Comb_Solid: Factores!$C$27:$C$51
Name Comb_liq: Factores!$C$6:$C$21
Name RANGO: 'Tabla Municipios'!$A$1:$F$1154
Name _xlchart.v1.0: Resultados!$C$6:$C$8
Name Comb_Gas: Factores!$C$56:$C$66
Name RANGO1: 'Tabla Municipios'!$A$1:$F$1154
Name Años: Factores!$C$81:$C$84
Name Extintores: Factores!$C$72:$C$74
Name _xlchart.v1.1: Resultados!$E$6:$E$8

Sheet Inicio
B3: CALCULADORA HUELLA DE CARBONO
B4: MUNDO VERDE
B5: CT-205-25-3 “Una apuesta por la adopción e implementación de prácticas sostenibles” "contrato de subvención 922-AIV.2/2023-045 (CV-119-24-2)"
B7: ESTIMACIÓN DE EMISIONES DE GASES DE EFECTO INVERNADERO (GEI)
C10: INGRESAR AÑO DE CÁLCULO | F10: 2024
B23: Fecha de elaboración 2025

Sheet Instructivo
A1: HERRAMIENTA EMISIONES GASES DE EFECTO INVERNADERO
A2: INSTRUCTIVO
A4: * Diligencie la herramienta de cálculo de emisiones de gases de efecto invernadero ingresando cada dato en el orden establecido,
A5: * Para las celdas que requieran ser diligenciadas con valores numéricos no incluir las unidades, estas son proporcionadas por la herramienta. Ejemplo: kg, galones, m3, grados (°), minutos ( ´ ), etcétera,
A6: * Cuando aparezca en el formulario "(Escoja Opción)" despliegue la lista para diligenciar la celda,
A7: * Si desea realizar el cálculo para más de un proceso deberá diligenciar un formulario por cada uno,
A8: * Recuerde que la información que diligencie debe corresponder a las cantidades del periodo de reporte.
A9: * Verifique antes de diligenciar la información de la empresa, que la herramienta no tenga ningún dato diligenciado,
A10: * Evite manipular la pestaña "Resumen". No ingrese ni borre información. Esta hoja de cálculo permite el correcto funcionamiento de la herramienta,
A11: * No elimine hojas de reportes ya creados. Para no afectar el funcionamiento de la herramienta no elimine reportes, dejelos sin diligenciar.
A12: GLOSARIO
A14: Depósitos de carbono: Son los compartimentos en donde se encuentra almacenado el carbono de los ecosistemas continentales y sus productos. Estos son: biomasa aérea y subterránea, materia orgánica muerta incluyendo detritos y madera muerta, carbono orgánico en el suelo y productos cosechados de la madera. Fuente: Resolución 1447 de 2018.
... A24: Potencial de Calentamiento Global (PCG): Factor que describe el impacto de la fuerza de radiación de una unidad con base en la masa de un GEI determinado, con relación a la unidad equivalente de dióxido de carbono en un periodo determinado. En ese sentido, se define como el efecto de calentamiento integrado a lo largo del tiempo que produce hoy una liberación instantánea de 1 kg de un gas de efecto invernadero, en comparación con el causado por el dióxido de carbono.

Sheet Infográfia
A1: INFOGRAFÍA Y GUÍAS RECOMENDADAS
A2: CAPITULO I. LA PROBLEMÁTICA MEDIO AMBIENTAL
A3: GUÍA MODULO 1. LOS PROBLEMAS MEDIO AMBIENTALES
A4: APLICAR HERRAMIENTA CALCULADORA HUELLA DE CARBONO

Sheet Corporativa
A1: EMISIONES HUELLA DE CARBONO CORPORATIVA
A2: La herramienta "Huella de carbono - MUNDO VERDE debe ser diligenciada con la información del año inmediatamente anterior. El objetivo es generar una buena práctica en el manejo y custodia de la información relacionada con la producción de gases de efecto invernado de su organización.
A3: INFORMACIÓN GENERAL DE LA ORGANIZACIÓN
A4: Nombre organización | B4: MIES
A5: Responsable | B5: DAVID GARCIA
A6: Número de trabajadores | B6: 10 | F6: Horas promedio de trabajo diario
A7: Departamento | B7: CALDAS | E7: Municipio | G7: MANIZALES
A8: Coordenadas | B8: Geográficas | E8: X | F8: 4.6372
E9: Y | F9: -75.292263
A10: Área construida (m2) | B10: 25000 | E10: Área total (m2) | G10: 45000 | J10: Temperatura promedio (°C) | K10: 18.5
A11: Período de reporte | B11: 2024
A12: Fecha de diligenciamiento (DD/MM/AÑO) | B12: 45877 | E12: Hora | G12: 08:00am
A13: Quién diligencia | B13: DAVID GARCIA
A14: Correo electrónico | B14: SBHGS@jbss.com | E14: Nro. Celular Contacto
A15: INVENTARIO DE EMISIONES CORPORATIVAS
A16: Diligencie la siguiente información referente a los vuelos corporativos realizados por los colaboradores de la organización
A17: Mes | B17: Ciudad Origen | C17: Ciudad Destino | D17: Clase | E17: Número de personas | F17: Tipo de vuelo | G17: Factor de Emisión (kgCO2e) | H17: Emisión (tCO2e) | K17: Emisión (kgCO2e)
A18: Enero | B18: Manizales | C18: Bogota | D18: Económica | E18: 2 | F18: Air Travel - Short Haul (< 482.8 km): 0.207 | G18: 0.207 | H18: =K18/1000 -> 0.000414 | K18: =G18*E18 -> 0.414
A19: Mayo | B19: Manizales | C19: Amsterdam | D19: Ejecutiva | E19: 20 | F19: Air Travel - Long Haul (>= 3701.49 km): 0.163 | G19: 0.163 | H19: =K19/1000 -> 0.00326 | K19: =G19*E19 -> 3.26
A20: Julio | B20: Medellin | C20: Bruselas | D20: Ejecutiva | E20: 200 | F20: Air Travel - Long Haul (>= 3701.49 km): 0.163 | G20: 0.163 | H20: =K20/1000 -> 0.0326 | K20: =G20*E20 -> 32.6
A21: Septiembre | B21: Ahmedabad | C21: Lome | D21: Ejecutiva | E21: 300 | F21: Air Travel - Medium Haul (>= 482.8 km, < 3701.49 km): 0.129 | G21: 0.129 | H21: =K21/1000 -> 0.0387 | K21: =G21*E21 -> 38.7
H22: =K22/1000 -> 0 | K22: =G22*E22 -> 0
H23: =K23/1000 -> 0 | K23: =G23*E23 -> 0
H24: =K24/1000 -> 0 | K24: =G24*E24 -> 0
H25: =K25/1000 -> 0 | K25: =G25*E25 -> 0
H26: =K26/1000 -> 0 | K26: =G26*E26 -> 0
H27: =K27/1000 -> 0 | K27: =G27*E27 -> 0
H28: =K28/1000 -> 0 | K28: =G28*E28 -> 0
H29: =K29/1000 -> 0 | K29: =G29*E29 -> 0
H30: =K30/1000 -> 0 | K30: =G30*E30 -> 0
H31: =SUM(H18:J30) -> 0.074974 | K31: =SUM(K18:L30) -> 74.974
A34: Vuelos corporativos | E34: Los vuelos corporativos suelen ser una fuente importante dentro de los inventarios de las organizaciones. En ese sentido, se recomienda adquirir los pasajes, en plataformas que permitan compensar las emisiones.
A35: =H31 -> 0.074974
A40: =H31/0.025 -> 2.99896 | C40: Siembra de Árboles

Sheet Factores
B3: FACTORES DE EMISION COMBUSTIBLES LÍQUIDOS
B5: No. | C5: Combustible | D5: Densidad (Kg/l) | E5: Poder Calorífico Inferior (LHV) MJ/kg | F5: Factor de emisión CO2 (Kg CO2 / TJ) | G5: Factor de emisión CH4 (Kg CH4 / TJ) | H5: Factor de emisión N2O (Kg N2O / TJ) aplicación estacionaria | I5: Factor de emisión N2O (Kg N2O / TJ) aplicación móvil | J5: Factor de emisión SO2 (Kg SO2 / TJ)
B6: 1 | C6: Kerosene | D6: 0.803 | E6: 42.8168 | F6: 73939.639 | G6: 3 | H6: 0.6 | I6: =H6 -> 0.6 | J6: 42.0002
B7: 2 | C7: Combustoleo | D7: 0.97 | E7: 39.3469 | F7: 80460.272 | G7: 3 | H7: 0.6 | I7: =H7 -> 0.6 | J7: 1269.5595
B8: 3 | C8: Crudo de Castilla | D8: 0.9414 | E8: 40.6705 | F8: 77841.778 | G8: 3 | H8: 0.6 | I8: =H8 -> 0.6 | J8: 1080.8539
B9: 4 | C9: Avigas | D9: 0.696 | E9: 43.0302 | F9: 56337.812 | G9: 3 | H9: 0.6 | I9: =H9 -> 0.6 | J9: 2.4146
B10: 5 | C10: Jet A1 | D10: 0.826 | E10: 35.5769 | F10: 88461.131 | G10: 3 | H10: 0.6 | I10: =H10 -> 0.6 | J10: 30.6653
B11: 6 | C11: Biodiesel palma | D11: 0.8751 | E11: 37.9079 | F11: 54806.487 | G11: 3 | H11: 0.6 | I11: 3.9 | J11: 2.4247
B12: 7 | C12: Etanol Anhidro | D12: 0.8208 | E12: 22.4802 | F12: 84758.116 | G12: 3 | H12: 0.6 | I12: 41 | J12: 4.0887
B13: 8 | C13: Fuel Oil # 4 - Ecopetrol | D13: 0.8493 | E13: 40.4422 | F13: 78281.203 | G13: 3 | H13: 0.6 | I13: =H13 -> 0.6 | J13: 0
B14: 9 | C14: Gasolina Motor | D14: 0.7405 | E14: 45.3295 | F14: 69323.686 | G14: 3 | H14: 0.6 | I14: 3.2 | J14: 3.5705
B15: 10 | C15: Diesel Marino | D15: 0.8576 | E15: 41.8694 | F15: 65207.203 | G15: 1 | H15: 0.6 | I15: 3.9 | J15: 4.3905
B16: 11 | C16: Diesel B2 | D16: 0.8519 | E16: 42.4185 | F16: 74193.483 | G16: 1 | H16: 0.6 | I16: 3.9 | J16: 2.9676
B17: 12 | C17: Gasolina E10 (Comercial) | D17: 0.7412 | E17: 40.6593 | F17: 66778.409 | G17: 3 | H17: 0.6 | I17: 3.2 | J17: 10.9589
B18: 13 | C18: GLP Cartagena | D18: 0.559 | E18: 45.4134 | F18: 67134.755 | G18: 1 | H18: 0.1 | I18: 3 | J18: 0
B19: 14 | C19: GLP Barrancabermeja | D19: 0.5864 | E19: 45.2318 | F19: 68911.812 | G19: 1 | H19: 0.1 | I19: 3 | J19: 0
B20: 15 | C20: GLP Cusiana | D20: 0.5343 | E20: 45.7431 | F20: 65846.382 | G20: 1 | H20: 0.1 | I20: 3 | J20: 0
B21: 16 | C21: GLP Genérico | D21: 0.5599 | E21: 45.4145 | F21: 67185.115 | G21: 1 | H21: 0.1 | I21: 3 | J21: 0
B24: FACTORES DE EMISIÓN COMBUSTIBLES SÓLIDOS
B26: No. | C26: Combustible | D26: Poder Calorífico Inferior (LHV) MJ/kg | E26: Factor de emisión CO2 (Kg CO2 / TJ) | F26: Factor de emisión CH4 (Kg CH4 / TJ) | G26: Factor de emisión N2O (Kg N2O / TJ) | H26: Factor de emisión SO2 (Kg SO2 / TJ)
B27: 1 | C27: Carbón Genérico | D27: 28.76 | E27: 88136.063 | F27: 1 | G27: 1.5 | H27: 3101.7541
B28: 2 | C28: Carbón Guajira - Cesar | D28: 26.622 | E28: 81163.156 | F28: 1 | G28: 1.5 | H28: 1133.7889
B29: 3 | C29: Carbón Guajira | D29: 30.417 | E29: 95146.446 | F29: 1 | G29: 1.5 | H29: 427.5182
B30: 4 | C30: Carbón Cundinamarca | D30: 29.17 | E30: 75915.075 | F30: 1 | G30: 1.5 | H30: 578.8202
B31: 5 | C31: Carbón Cauca - Valle del Cauca | D31: 31.212 | E31: 80341.198 | F31: 1 | G31: 1.5 | H31: 10011.704
B32: 6 | C32: Carbón Norte de Santander | D32: 31.229 | E32: 90067.894 | F32: 1 | G32: 1.5 | H32: 671.8226
B33: 7 | C33: Carbón Córdoba-Norte de Antioquia | D33: 20.948 | E33: 90854.391 | F33: 1 | G33: 1.5 | H33: 1430.7775
B34: 8 | C34: Carbón Santander | D34: 33.077 | E34: 77405.145 | F34: 1 | G34: 1.5 | H34: 11860.282
B35: 9 | C35: Carbón Santander Sogamoso | D35: 29.205 | E35: 92142.041 | F35: 1 | G35: 1.5 | H35: 738.9073
B36: 10 | C36: Carbón Boyacá | D36: 35.206 | E36: 86711.847 | F36: 1 | G36: 1.5 | H36: 308.9193
B37: 11 | C37: Carbón Antioquia | D37: 24.405 | E37: 93317.311 | F37: 1 | G37: 1.5 | H37: 1399.6315
B38: 12 | C38: Bagazo | D38: 14.743 | E38: 112929.72 | F38: 30 | G38: 4 | H38: 47.4357
... B51: 25 | C51: Residuos de llantas | D51: 37.921 | E51: 77577.488 | F51: 30 | G51: 0.1 | H51: 1124.9715
B53: FACTORES DE EMISIÓN COMBUSTIBLES GASEOSOS
B55: No. | C55: Combustible | D55: Poder Calorífico Inferior (LHV) MJ/m3 | E55: Factor de emisión CO2 (Kg CO2 / TJ) | F55: Factor de emisión CH4 (Kg CH4 / TJ) | G55: Factor de emisión N2O (Kg N2O / TJ) aplicación estacionaria | H55: Factor de emisión N2O (Kg N2O / TJ) aplicación móvil
B56: 1 | C56: Biogas Genérico | D56: 22.0001 | E56: 84364.418 | F56: 1 | G56: 0.1 | H56: =G56 -> 0.1
B57: 2 | C57: Coke Gas Genérico | D57: 15.0252 | E57: 40784.042 | F57: 1 | G57: 0.1 | H57: =G57 -> 0.1
B58: 3 | C58: Gas Natural Cusiana | D58: 38.6735 | E58: 56647.783 | F58: 1 | G58: 0.1 | H58: 3
B59: 4 | C59: Gas Natural Guajira | D59: 33.4943 | E59: 54911.342 | F59: 1 | G59: 0.1 | H59: 3
B60: 5 | C60: Gas Natural Guepaje | D60: 33.2687 | E60: 54869.575 | F60: 1 | G60: 0.1 | H60: 3
...

Sheet Combustibles Líquidos
B1: ALCANCE 1. EMISIONES DIRECTAS POR CONSUMO DE COMBUSTIBLES FÓSILES LIQUIDOS DE FUENTES ESTACIONARIAS
B3: No. | C3: Combustibles | D3: Consumo anual (gal) | E3: Consumo anual (l) | F3: Densidad (kg/l) | G3: Masa de combustible (kg) | H3: Poder calorífico (MJ/kg) | I3: Consumo de energía (TJ) | J3: Factor de emisión CO2 (Kg CO2 / TJ) | K3: Factor de emisión CH4 (Kg CH4 / TJ) | L3: Factor de emisión N2O (Kg N2O / TJ) | M3: Factor de emisión SO2 (Kg SO2 / TJ) | N3: Emisión CO2 (Kg CO2 / TJ) | O3: Emisión CH4 (Kg CH4 / TJ) | P3: Emisión N2O (Kg N2O / TJ) | Q3: Emisión SO2 (Kg SO2 / TJ) | R3: EMISIONES TOTALES (Ton CO2 eq)
B4: 1 | R4: =SUM(N20,O20,P20,Q20)/1000 -> 0.42368241
B5: 2
B6: 3
B7: 4
B8: 5 | C8: Kerosene | D8: 44 | E8: =D8*3.78541 -> 166.55804 | F8: =IF($C8="Kerosene",Factores!$D$6,IF($C8="Combustoleo",Factores!$D$7,IF($C8="Crudo de Castilla",Factores!$D$8,IF($C8="Avigas",Factores!$D$9,IF($C8="Jet A1",Factores!$D$10,IF($C8="Biodiesel palma",Factores!$D$11,IF($C8="Etanol Anhidro",Factores!$D$12,IF($C8="Fuel Oil # 4 - Ecopetrol",Factores!$D$13, IF($C8="Gasolina Motor",Factores!$D$14,IF($C8="Diesel Marino",Factores!$D$15,IF($C8="Diesel B2",Factores!$D$16,IF($C8="Gasolina E10 (Comercial)",Factores!$D$17,IF($C8="GLP Cartagena",Factores!$D$18,IF($C8="GLP Barrancabermeja",Factores!$D$19,IF($C8="GLP Cusiana",Factores!$D$20,IF($C8="GLP Genérico",Factores!$D$21, "0")))))))))))))))) -> 0.803 | G8: =E8*F8 -> 133.74611 | H8: =IF($C8="Kerosene",Factores!$E$6,IF($C8="Combustoleo",Factores!$E$7,IF($C8="Crudo de Castilla",Factores!$E$8,IF($C8="Avigas",Factores!$E$9,IF($C8="Jet A1",Factores!$E$10,IF($C8="Biodiesel palma",Factores!$E$11,IF($C8="Etanol Anhidro",Factores!$E$12,IF($C8="Fuel Oil # 4 - Ecopetrol",Factores!$E$13, IF($C8="Gasolina Motor",Factores!$E$14,IF($C8="Diesel Marino",Factores!$E$15,IF($C8="Diesel B2",Factores!$E$16,IF($C8="Gasolina E10 (Comercial)",Factores!$E$17,IF($C8="GLP Cartagena",Factores!$E$18,IF($C8="GLP Barrancabermeja",Factores!$E$19,IF($C8="GLP Cusiana",Factores!$E$20,IF($C8="GLP Genérico",Factores!$E$21, "0")))))))))))))))) -> 42.8168 | I8: =(H8*G8)/1000000 -> 0.0057265803 | J8: =IF($C8="Kerosene",Factores!$F$6,IF($C8="Combustoleo",Factores!$F$7,IF($C8="Crudo de Castilla",Factores!$F$8,IF($C8="Avigas",Factores!$F$9,IF($C8="Jet A1",Factores!$F$10,IF($C8="Biodiesel palma",Factores!$F$11,IF($C8="Etanol Anhidro",Factores!$F$12,IF($C8="Fuel Oil # 4 - Ecopetrol",Factores!$F$13, IF($C8="Gasolina Motor",Factores!$F$14,IF($C8="Diesel Marino",Factores!$F$15,IF($C8="Diesel B2",Factores!$F$16,IF($C8="Gasolina E10 (Comercial)",Factores!$F$17,IF($C8="GLP Cartagena",Factores!$F$18,IF($C8="GLP Barrancabermeja",Factores!$F$19,IF($C8="GLP Cusiana",Factores!$F$20,IF($C8="GLP Genérico",Factores!$F$21, "0")))))))))))))))) -> 73939.639 | K8: =IF($C8="Kerosene",Factores!$G$6,IF($C8="Combustoleo",Factores!$G$7,IF($C8="Crudo de Castilla",Factores!$G$8,IF($C8="Avigas",Factores!$G$9,IF($C8="Jet A1",Factores!$G$10,IF($C8="Biodiesel palma",Factores!$G$11,IF($C8="Etanol Anhidro",Factores!$G$12,IF($C8="Fuel Oil # 4 - Ecopetrol",Factores!$G$13, IF($C8="Gasolina Motor",Factores!$G$14,IF($C8="Diesel Marino",Factores!$G$15,IF($C8="Diesel B2",Factores!$G$16,IF($C8="Gasolina E10 (Comercial)",Factores!$G$17,IF($C8="GLP Cartagena",Factores!$G$18,IF($C8="GLP Barrancabermeja",Factores!$G$19,IF($C8="GLP Cusiana",Factores!$G$20,IF($C8="GLP Genérico",Factores!$G$21, "0")))))))))))))))) -> 3 | L8: =IF($C8="Kerosene",Factores!$H$6,IF($C8="Combustoleo",Factores!$H$7,IF($C8="Crudo de Castilla",Factores!$H$8,IF($C8="Avigas",Factores!$H$9,IF($C8="Jet A1",Factores!$H$10,IF($C8="Biodiesel palma",Factores!$H$11,IF($C8="Etanol Anhidro",Factores!$H$12,IF($C8="Fuel Oil # 4 - Ecopetrol",Factores!$H$13, IF($C8="Gasolina Motor",Factores!$H$14,IF($C8="Diesel Marino",Factores!$H$15,IF($C8="Diesel B2",Factores!$H$16,IF($C8="Gasolina E10 (Comercial)",Factores!$H$17,IF($C8="GLP Cartagena",Factores!$H$18,IF($C8="GLP Barrancabermeja",Factores!$H$19,IF($C8="GLP Cusiana",Factores!$H$20,IF($C8="GLP Genérico",Factores!$H$21, "0")))))))))))))))) -> 0.6 | M8: =IF($C8="Kerosene",Factores!$J$6,IF($C8="Combustoleo",Factores!$J$7,IF($C8="Crudo de Castilla",Factores!$J$8,IF($C8="Avigas",Factores!$J$9,IF($C8="Jet A1",Factores!$J$10,IF($C8="Biodiesel palma",Factores!$J$11,IF($C8="Etanol Anhidro",Factores!$J$12,IF($C8="Fuel Oil # 4 - Ecopetrol",Factores!$J$13, IF($C8="Gasolina Motor",Factores!$J$14,IF($C8="Diesel Marino",Factores!$J$15,IF($C8="Diesel B2",Factores!$J$16,IF($C8="Gasolina E10 (Comercial)",Factores!$J$17,IF($C8="GLP Cartagena",Factores!$J$18,IF($C8="GLP Barrancabermeja",Factores!$J$19,IF($C8="GLP Cusiana",Factores!$J$20,IF($C8="GLP Genérico",Factores!$J$21, "0")))))))))))))))) -> 42.0002 | N8: =$J8*$I8 -> 423.42128 | O8: =$K8*$I8 -> 0.017179741 | P8: =$I8*$L8 -> 0.0034359482 | Q8: =$I8*$M8 -> 0.24051752
B9: 6 | E9: =D9*3.78541 -> 0 | F9: =IF($C9="Kerosene",Factores!$D$6,IF($C9="Combustoleo",Factores!$D$7,IF($C9="Crudo de Castilla",Factores!$D$8,IF($C9="Avigas",Factores!$D$9,IF($C9="Jet A1",Factores!$D$10,IF($C9="Biodiesel palma",Factores!$D$11,IF($C9="Etanol Anhidro",Factores!$D$12,IF($C9="Fuel Oil # 4 - Ecopetrol",Factores!$D$13, IF($C9="Gasolina Motor",Factores!$D$14,IF($C9="Diesel Marino",Factores!$D$15,IF($C9="Diesel B2",Factores!$D$16,IF($C9="Gasolina E10 (Comercial)",Factores!$D$17,IF($C9="GLP Cartagena",Factores!$D$18,IF($C9="GLP Barrancabermeja",Factores!$D$19,IF($C9="GLP Cusiana",Factores!$D$20,IF($C9="GLP Genérico",Factores!$D$21, "0")))))))))))))))) -> 0 | G9: =E9*F9 -> 0 | H9: =IF($C9="Kerosene",Factores!$E$6,IF($C9="Combustoleo",Factores!$E$7,IF($C9="Crudo de Castilla",Factores!$E$8,IF($C9="Avigas",Factores!$E$9,IF($C9="Jet A1",Factores!$E$10,IF($C9="Biodiesel palma",Factores!$E$11,IF($C9="Etanol Anhidro",Factores!$E$12,IF($C9="Fuel Oil # 4 - Ecopetrol",Factores!$E$13, IF($C9="Gasolina Motor",Factores!$E$14,IF($C9="Diesel Marino",Factores!$E$15,IF($C9="Diesel B2",Factores!$E$16,IF($C9="Gasolina E10 (Comercial)",Factores!$E$17,IF($C9="GLP Cartagena",Factores!$E$18,IF($C9="GLP Barrancabermeja",Factores!$E$19,IF($C9="GLP Cusiana",Factores!$E$20,IF($C9="GLP Genérico",Factores!$E$21, "0")))))))))))))))) -> 0 | I9: =(H9*G9)/1000000 -> 0 | J9: =IF($C9="Kerosene",Factores!$F$6,IF($C9="Combustoleo",Factores!$F$7,IF($C9="Crudo de Castilla",Factores!$F$8,IF($C9="Avigas",Factores!$F$9,IF($C9="Jet A1",Factores!$F$10,IF($C9="Biodiesel palma",Factores!$F$11,IF($C9="Etanol Anhidro",Factores!$F$12,IF($C9="Fuel Oil # 4 - Ecopetrol",Factores!$F$13, IF($C9="Gasolina Motor",Factores!$F$14,IF($C9="Diesel Marino",Factores!$F$15,IF($C9="Diesel B2",Factores!$F$16,IF($C9="Gasolina E10 (Comercial)",Factores!$F$17,IF($C9="GLP Cartagena",Factores!$F$18,IF($C9="GLP Barrancabermeja",Factores!$F$19,IF($C9="GLP Cusiana",Factores!$F$20,IF($C9="GLP Genérico",Factores!$F$21, "0")))))))))))))))) -> 0 | K9: =IF($C9="Kerosene",Factores!$G$6,IF($C9="Combustoleo",Factores!$G$7,IF($C9="Crudo de Castilla",Factores!$G$8,IF($C9="Avigas",Factores!$G$9,IF($C9="Jet A1",Factores!$G$10,IF($C9="Biodiesel palma",Factores!$G$11,IF($C9="Etanol Anhidro",Factores!$G$12,IF($C9="Fuel Oil # 4 - Ecopetrol",Factores!$G$13, IF($C9="Gasolina Motor",Factores!$G$14,IF($C9="Diesel Marino",Factores!$G$15,IF($C9="Diesel B2",Factores!$G$16,IF($C9="Gasolina E10 (Comercial)",Factores!$G$17,IF($C9="GLP Cartagena",Factores!$G$18,IF($C9="GLP Barrancabermeja",Factores!$G$19,IF($C9="GLP Cusiana",Factores!$G$20,IF($C9="GLP Genérico",Factores!$G$21, "0")))))))))))))))) -> 0 | L9: =IF($C9="Kerosene",Factores!$H$6,IF($C9="Combustoleo",Factores!$H$7,IF($C9="Crudo de Castilla",Factores!$H$8,IF($C9="Avigas",Factores!$H$9,IF($C9="Jet A1",Factores!$H$10,IF($C9="Biodiesel palma",Factores!$H$11,IF($C9="Etanol Anhidro",Factores!$H$12,IF($C9="Fuel Oil # 4 - Ecopetrol",Factores!$H$13, IF($C9="Gasolina Motor",Factores!$H$14,IF($C9="Diesel Marino",Factores!$H$15,IF($C9="Diesel B2",Factores!$H$16,IF($C9="Gasolina E10 (Comercial)",Factores!$H$17,IF($C9="GLP Cartagena",Factores!$H$18,IF($C9="GLP Barrancabermeja",Factores!$H$19,IF($C9="GLP Cusiana",Factores!$H$20,IF($C9="GLP Genérico",Factores!$H$21, "0")))))))))))))))) -> 0 | M9: =IF($C9="Kerosene",Factores!$J$6,IF($C9="Combustoleo",Factores!$J$7,IF($C9="Crudo de Castilla",Factores!$J$8,IF($C9="Avigas",Factores!$J$9,IF($C9="Jet A1",Factores!$J$10,IF($C9="Biodiesel palma",Factores!$J$11,IF($C9="Etanol Anhidro",Factores!$J$12,IF($C9="Fuel Oil # 4 - Ecopetrol",Factores!$J$13, IF($C9="Gasolina Motor",Factores!$J$14,IF($C9="Diesel Marino",Factores!$J$15,IF($C9="Diesel B2",Factores!$J$16,IF($C9="Gasolina E10 (Comercial)",Factores!$J$17,IF($C9="GLP Cartagena",Factores!$J$18,IF($C9="GLP Barrancabermeja",Factores!$J$19,IF($C9="GLP Cusiana",Factores!$J$20,IF($C9="GLP Genérico",Factores!$J$21, "0")))))))))))))))) -> 0 | N9: =$J9*$I9 -> 0 | O9: =$K9*$I9 -> 0 | P9: =$I9*$L9 -> 0 | Q9: =$I9*$M9 -> 0
B10: 7 | E10: =D10*3.78541 -> 0 | F10: =IF($C10="Kerosene",Factores!$D$6,IF($C10="Combustoleo",Factores!$D$7,IF($C10="Crudo de Castilla",Factores!$D$8,IF($C10="Avigas",Factores!$D$9,IF($C10="Jet A1",Factores!$D$10,IF($C10="Biodiesel palma",Factores!$D$11,IF($C10="Etanol Anhidro",Factores!$D$12,IF($C10="Fuel Oil # 4 - Ecopetrol",Factores!$D$13, IF($C10="Gasolina Motor",Factores!$D$14,IF($C10="Diesel Marino",Factores!$D$15,IF($C10="Diesel B2",Factores!$D$16,IF($C10="Gasolina E10 (Comercial)",Factores!$D$17,IF($C10="GLP Cartagena",Factores!$D$18,IF($C10="GLP Barrancabermeja",Factores!$D$19,IF($C10="GLP Cusiana",Factores!$D$20,IF($C10="GLP Genérico",Factores!$D$21, "0")))))))))))))))) -> 0 | G10: =E10*F10 -> 0 | H10: =IF($C10="Kerosene",Factores!$E$6,IF($C10="Combustoleo",Factores!$E$7,IF($C10="Crudo de Castilla",Factores!$E$8,IF($C10="Avigas",Factores!$E$9,IF($C10="Jet A1",Factores!$E$10,IF($C10="Biodiesel palma",Factores!$E$11,IF($C10="Etanol Anhidro",Factores!$E$12,IF($C10="Fuel Oil # 4 - Ecopetrol",Factores!$E$13, IF($C10="Gasolina Motor",Factores!$E$14,IF($C10="Diesel Marino",Factores!$E$15,IF($C10="Diesel B2",Factores!$E$16,IF($C10="Gasolina E10 (Comercial)",Factores!$E$17,IF($C10="GLP Cartagena",Factores!$E$18,IF($C10="GLP Barrancabermeja",Factores!$E$19,IF($C10="GLP Cusiana",Factores!$E$20,IF($C10="GLP Genérico",Factores!$E$21, "0")))))))))))))))) -> 0 | I10: =(H10*G10)/1000000 -> 0 | J10: =IF($C10="Kerosene",Factores!$F$6,IF($C10="Combustoleo",Factores!$F$7,IF($C10="Crudo de Castilla",Factores!$F$8,IF($C10="Avigas",Factores!$F$9,IF($C10="Jet A1",Factores!$F$10,IF($C10="Biodiesel palma",Factores!$F$11,IF($C10="Etanol Anhidro",Factores!$F$12,IF($C10="Fuel Oil # 4 - Ecopetrol",Factores!$F$13, IF($C10="Gasolina Motor",Factores!$F$14,IF($C10="Diesel Marino",Factores!$F$15,IF($C10="Diesel B2",Factores!$F$16,IF($C10="Gasolina E10 (Comercial)",Factores!$F$17,IF($C10="GLP Cartagena",Factores!$F$18,IF($C10="GLP Barrancabermeja",Factores!$F$19,IF($C10="GLP Cusiana",Factores!$F$20,IF($C10="GLP Genérico",Factores!$F$21, "0")))))))))))))))) -> 0 | K10: =IF($C10="Kerosene",Factores!$G$6,IF($C10="Combustoleo",Factores!$G$7,IF($C10="Crudo de Castilla",Factores!$G$8,IF($C10="Avigas",Factores!$G$9,IF($C10="Jet A1",Factores!$G$10,IF($C10="Biodiesel palma",Factores!$G$11,IF($C10="Etanol Anhidro",Factores!$G$12,IF($C10="Fuel Oil # 4 - Ecopetrol",Factores!$G$13, IF($C10="Gasolina Motor",Factores!$G$14,IF($C10="Diesel Marino",Factores!$G$15,IF($C10="Diesel B2",Factores!$G$16,IF($C10="Gasolina E10 (Comercial)",Factores!$G$17,IF($C10="GLP Cartagena",Factores!$G$18,IF($C10="GLP Barrancabermeja",Factores!$G$19,IF($C10="GLP Cusiana",Factores!$G$20,IF($C10="GLP Genérico",Factores!$G$21, "0")))))))))))))))) -> 0 | L10: =IF($C10="Kerosene",Factores!$H$6,IF($C10="Combustoleo",Factores!$H$7,IF($C10="Crudo de Castilla",Factores!$H$8,IF($C10="Avigas",Factores!$H$9,IF($C10="Jet A1",Factores!$H$10,IF($C10="Biodiesel palma",Factores!$H$11,IF($C10="Etanol Anhidro",Factores!$H$12,IF($C10="Fuel Oil # 4 - Ecopetrol",Factores!$H$13, IF($C10="Gasolina Motor",Factores!$H$14,IF($C10="Diesel Marino",Factores!$H$15,IF($C10="Diesel B2",Factores!$H$16,IF($C10="Gasolina E10 (Comercial)",Factores!$H$17,IF($C10="GLP Cartagena",Factores!$H$18,IF($C10="GLP Barrancabermeja",Factores!$H$19,IF($C10="GLP Cusiana",Factores!$H$20,IF($C10="GLP Genérico",Factores!$H$21, "0")))))))))))))))) -> 0 | M10: =IF($C10="Kerosene",Factores!$J$6,IF($C10="Combustoleo",Factores!$J$7,IF($C10="Crudo de Castilla",Factores!$J$8,IF($C10="Avigas",Factores!$J$9,IF($C10="Jet A1",Factores!$J$10,IF($C10="Biodiesel palma",Factores!$J$11,IF($C10="Etanol Anhidro",Factores!$J$12,IF($C10="Fuel Oil # 4 - Ecopetrol",Factores!$J$13, IF($C10="Gasolina Motor",Factores!$J$14,IF($C10="Diesel Marino",Factores!$J$15,IF($C10="Diesel B2",Factores!$J$16,IF($C10="Gasolina E10 (Comercial)",Factores!$J$17,IF($C10="GLP Cartagena",Factores!$J$18,IF($C10="GLP Barrancabermeja",Factores!$J$19,IF($C10="GLP Cusiana",Factores!$J$20,IF($C10="GLP Genérico",Factores!$J$21, "0")))))))))))))))) -> 0 | N10: =$J10*$I10 -> 0 | O10: =$K10*$I10 -> 0 | P10: =$I10*$L10 -> 0 | Q10: =$I10*$M10 -> 0
B11: 8 | E11: =D11*3.78541 -> 0 | F11: =IF($C11="Kerosene",Factores!$D$6,IF($C11="Combustoleo",Factores!$D$7,IF($C11="Crudo de Castilla",Factores!$D$8,IF($C11="Avigas",Factores!$D$9,IF($C11="Jet A1",Factores!$D$10,IF($C11="Biodiesel palma",Factores!$D$11,IF($C11="Etanol Anhidro",Factores!$D$12,IF($C11="Fuel Oil # 4 - Ecopetrol",Factores!$D$13, IF($C11="Gasolina Motor",Factores!$D$14,IF($C11="Diesel Marino",Factores!$D$15,IF($C11="Diesel B2",Factores!$D$16,IF($C11="Gasolina E10 (Comercial)",Factores!$D$17,IF($C11="GLP Cartagena",Factores!$D$18,IF($C11="GLP Barrancabermeja",Factores!$D$19,IF($C11="GLP Cusiana",Factores!$D$20,IF($C11="GLP Genérico",Factores!$D$21, "0")))))))))))))))) -> 0 | G11: =E11*F11 -> 0 | H11: =IF($C11="Kerosene",Factores!$E$6,IF($C11="Combustoleo",Factores!$E$7,IF($C11="Crudo de Castilla",Factores!$E$8,IF($C11="Avigas",Factores!$E$9,IF($C11="Jet A1",Factores!$E$10,IF($C11="Biodiesel palma",Factores!$E$11,IF($C11="Etanol Anhidro",Factores!$E$12,IF($C11="Fuel Oil # 4 - Ecopetrol",Factores!$E$13, IF($C11="Gasolina Motor",Factores!$E$14,IF($C11="Diesel Marino",Factores!$E$15,IF($C11="Diesel B2",Factores!$E$16,IF($C11="Gasolina E10 (Comercial)",Factores!$E$17,IF($C11="GLP Cartagena",Factores!$E$18,IF($C11="GLP Barrancabermeja",Factores!$E$19,IF($C11="GLP Cusiana",Factores!$E$20,IF($C11="GLP Genérico",Factores!$E$21, "0")))))))))))))))) -> 0 | I11: =(H11*G11)/1000000 -> 0 | J11: =IF($C11="Kerosene",Factores!$F$6,IF($C11="Combustoleo",Factores!$F$7,IF($C11="Crudo de Castilla",Factores!$F$8,IF($C11="Avigas",Factores!$F$9,IF($C11="Jet A1",Factores!$F$10,IF($C11="Biodiesel palma",Factores!$F$11,IF($C11="Etanol Anhidro",Factores!$F$12,IF($C11="Fuel Oil # 4 - Ecopetrol",Factores!$F$13, IF($C11="Gasolina Motor",Factores!$F$14,IF($C11="Diesel Marino",Factores!$F$15,IF($C11="Diesel B2",Factores!$F$16,IF($C11="Gasolina E10 (Comercial)",Factores!$F$17,IF($C11="GLP Cartagena",Factores!$F$18,IF($C11="GLP Barrancabermeja",Factores!$F$19,IF($C11="GLP Cusiana",Factores!$F$20,IF($C11="GLP Genérico",Factores!$F$21, "0")))))))))))))))) -> 0 | K11: =IF($C11="Kerosene",Factores!$G$6,IF($C11="Combustoleo",Factores!$G$7,IF($C11="Crudo de Castilla",Factores!$G$8,IF($C11="Avigas",Factores!$G$9,IF($C11="Jet A1",Factores!$G$10,IF($C11="Biodiesel palma",Factores!$G$11,IF($C11="Etanol Anhidro",Factores!$G$12,IF($C11="Fuel Oil # 4 - Ecopetrol",Factores!$G$13, IF($C11="Gasolina Motor",Factores!$G$14,IF($C11="Diesel Marino",Factores!$G$15,IF($C11="Diesel B2",Factores!$G$16,IF($C11="Gasolina E10 (Comercial)",Factores!$G$17,IF($C11="GLP Cartagena",Factores!$G$18,IF($C11="GLP Barrancabermeja",Factores!$G$19,IF($C11="GLP Cusiana",Factores!$G$20,IF($C11="GLP Genérico",Factores!$G$21, "0")))))))))))))))) -> 0 | L11: =IF($C11="Kerosene",Factores!$H$6,IF($C11="Combustoleo",Factores!$H$7,IF($C11="Crudo de Castilla",Factores!$H$8,IF($C11="Avigas",Factores!$H$9,IF($C11="Jet A1",Factores!$H$10,IF($C11="Biodiesel palma",Factores!$H$11,IF($C11="Etanol Anhidro",Factores!$H$12,IF($C11="Fuel Oil # 4 - Ecopetrol",Factores!$H$13, IF($C11="Gasolina Motor",Factores!$H$14,IF($C11="Diesel Marino",Factores!$H$15,IF($C11="Diesel B2",Factores!$H$16,IF($C11="Gasolina E10 (Comercial)",Factores!$H$17,IF($C11="GLP Cartagena",Factores!$H$18,IF($C11="GLP Barrancabermeja",Factores!$H$19,IF($C11="GLP Cusiana",Factores!$H$20,IF($C11="GLP Genérico",Factores!$H$21, "0")))))))))))))))) -> 0 | M11: =IF($C11="Kerosene",Factores!$J$6,IF($C11="Combustoleo",Factores!$J$7,IF($C11="Crudo de Castilla",Factores!$J$8,IF($C11="Avigas",Factores!$J$9,IF($C11="Jet A1",Factores!$J$10,IF($C11="Biodiesel palma",Factores!$J$11,IF($C11="Etanol Anhidro",Factores!$J$12,IF($C11="Fuel Oil # 4 - Ecopetrol",Factores!$J$13, IF($C11="Gasolina Motor",Factores!$J$14,IF($C11="Diesel Marino",Factores!$J$15,IF($C11="Diesel B2",Factores!$J$16,IF($C11="Gasolina E10 (Comercial)",Factores!$J$17,IF($C11="GLP Cartagena",Factores!$J$18,IF($C11="GLP Barrancabermeja",Factores!$J$19,IF($C11="GLP Cusiana",Factores!$J$20,IF($C11="GLP Genérico",Factores!$J$21, "0")))))))))))))))) -> 0 | N11: =$J11*$I11 -> 0 | O11: =$K11*$I11 -> 0 | P11: =$I11*$L11 -> 0 | Q11: =$I11*$M11 -> 0
B12: 9 | E12: =D12*3.78541 -> 0 | F12: =IF($C12="Kerosene",Factores!$D$6,IF($C12="Combustoleo",Factores!$D$7,IF($C12="Crudo de Castilla",Factores!$D$8,IF($C12="Avigas",Factores!$D$9,IF($C12="Jet A1",Factores!$D$10,IF($C12="Biodiesel palma",Factores!$D$11,IF($C12="Etanol Anhidro",Factores!$D$12,IF($C12="Fuel Oil # 4 - Ecopetrol",Factores!$D$13, IF($C12="Gasolina Motor",Factores!$D$14,IF($C12="Diesel Marino",Factores!$D$15,IF($C12="Diesel B2",Factores!$D$16,IF($C12="Gasolina E10 (Comercial)",Factores!$D$17,IF($C12="GLP Cartagena",Factores!$D$18,IF($C12="GLP Barrancabermeja",Factores!$D$19,IF($C12="GLP Cusiana",Factores!$D$20,IF($C12="GLP Genérico",Factores!$D$21, "0")))))))))))))))) -> 0 | G12: =E12*F12 -> 0 | H12: =IF($C12="Kerosene",Factores!$E$6,IF($C12="Combustoleo",Factores!$E$7,IF($C12="Crudo de Castilla",Factores!$E$8,IF($C12="Avigas",Factores!$E$9,IF($C12="Jet A1",Factores!$E$10,IF($C12="Biodiesel palma",Factores!$E$11,IF($C12="Etanol Anhidro",Factores!$E$12,IF($C12="Fuel Oil # 4 - Ecopetrol",Factores!$E$13, IF($C12="Gasolina Motor",Factores!$E$14,IF($C12="Diesel Marino",Factores!$E$15,IF($C12="Diesel B2",Factores!$E$16,IF($C12="Gasolina E10 (Comercial)",Factores!$E$17,IF($C12="GLP Cartagena",Factores!$E$18,IF($C12="GLP Barrancabermeja",Factores!$E$19,IF($C12="GLP Cusiana",Factores!$E$20,IF($C12="GLP Genérico",Factores!$E$21, "0")))))))))))))))) -> 0 | I12: =(H12*G12)/1000000 -> 0 | J12: =IF($C12="Kerosene",Factores!$F$6,IF($C12="Combustoleo",Factores!$F$7,IF($C12="Crudo de Castilla",Factores!$F$8,IF($C12="Avigas",Factores!$F$9,IF($C12="Jet A1",Factores!$F$10,IF($C12="Biodiesel palma",Factores!$F$11,IF($C12="Etanol Anhidro",Factores!$F$12,IF($C12="Fuel Oil # 4 - Ecopetrol",Factores!$F$13, IF($C12="Gasolina Motor",Factores!$F$14,IF($C12="Diesel Marino",Factores!$F$15,IF($C12="Diesel B2",Factores!$F$16,IF($C12="Gasolina E10 (Comercial)",Factores!$F$17,IF($C12="GLP Cartagena",Factores!$F$18,IF($C12="GLP Barrancabermeja",Factores!$F$19,IF($C12="GLP Cusiana",Factores!$F$20,IF($C12="GLP Genérico",Factores!$F$21, "0")))))))))))))))) -> 0 | K12: =IF($C12="Kerosene",Factores!$G$6,IF($C12="Combustoleo",Factores!$G$7,IF($C12="Crudo de Castilla",Factores!$G$8,IF($C12="Avigas",Factores!$G$9,IF($C12="Jet A1",Factores!$G$10,IF($C12="Biodiesel palma",Factores!$G$11,IF($C12="Etanol Anhidro",Factores!$G$12,IF($C12="Fuel Oil # 4 - Ecopetrol",Factores!$G$13, IF($C12="Gasolina Motor",Factores!$G$14,IF($C12="Diesel Marino",Factores!$G$15,IF($C12="Diesel B2",Factores!$G$16,IF($C12="Gasolina E10 (Comercial)",Factores!$G$17,IF($C12="GLP Cartagena",Factores!$G$18,IF($C12="GLP Barrancabermeja",Factores!$G$19,IF($C12="GLP Cusiana",Factores!$G$20,IF($C12="GLP Genérico",Factores!$G$21, "0")))))))))))))))) -> 0 | L12: =IF($C12="Kerosene",Factores!$H$6,IF($C12="Combustoleo",Factores!$H$7,IF($C12="Crudo de Castilla",Factores!$H$8,IF($C12="Avigas",Factores!$H$9,IF($C12="Jet A1",Factores!$H$10,IF($C12="Biodiesel palma",Factores!$H$11,IF($C12="Etanol Anhidro",Factores!$H$12,IF($C12="Fuel Oil # 4 - Ecopetrol",Factores!$H$13, IF($C12="Gasolina Motor",Factores!$H$14,IF($C12="Diesel Marino",Factores!$H$15,IF($C12="Diesel B2",Factores!$H$16,IF($C12="Gasolina E10 (Comercial)",Factores!$H$17,IF($C12="GLP Cartagena",Factores!$H$18,IF($C12="GLP Barrancabermeja",Factores!$H$19,IF($C12="GLP Cusiana",Factores!$H$20,IF($C12="GLP Genérico",Factores!$H$21, "0")))))))))))))))) -> 0 | M12: =IF($C12="Kerosene",Factores!$J$6,IF($C12="Combustoleo",Factores!$J$7,IF($C12="Crudo de Castilla",Factores!$J$8,IF($C12="Avigas",Factores!$J$9,IF($C12="Jet A1",Factores!$J$10,IF($C12="Biodiesel palma",Factores!$J$11,IF($C12="Etanol Anhidro",Factores!$J$12,IF($C12="Fuel Oil # 4 - Ecopetrol",Factores!$J$13, IF($C12="Gasolina Motor",Factores!$J$14,IF($C12="Diesel Marino",Factores!$J$15,IF($C12="Diesel B2",Factores!$J$16,IF($C12="Gasolina E10 (Comercial)",Factores!$J$17,IF($C12="GLP Cartagena",Factores!$J$18,IF($C12="GLP Barrancabermeja",Factores!$J$19,IF($C12="GLP Cusiana",Factores!$J$20,IF($C12="GLP Genérico",Factores!$J$21, "0")))))))))))))))) -> 0 | N12: =$J12*$I12 -> 0 | O12: =$K12*$I12 -> 0 | P12: =$I12*$L12 -> 0 | Q12: =$I12*$M12 -> 0
B13: 10 | E13: =D13*3.78541 -> 0 | F13: =IF($C13="Kerosene",Factores!$D$6,IF($C13="Combustoleo",Factores!$D$7,IF($C13="Crudo de Castilla",Factores!$D$8,IF($C13="Avigas",Factores!$D$9,IF($C13="Jet A1",Factores!$D$10,IF($C13="Biodiesel palma",Factores!$D$11,IF($C13="Etanol Anhidro",Factores!$D$12,IF($C13="Fuel Oil # 4 - Ecopetrol",Factores!$D$13, IF($C13="Gasolina Motor",Factores!$D$14,IF($C13="Diesel Marino",Factores!$D$15,IF($C13="Diesel B2",Factores!$D$16,IF($C13="Gasolina E10 (Comercial)",Factores!$D$17,IF($C13="GLP Cartagena",Factores!$D$18,IF($C13="GLP Barrancabermeja",Factores!$D$19,IF($C13="GLP Cusiana",Factores!$D$20,IF($C13="GLP Genérico",Factores!$D$21, "0")))))))))))))))) -> 0 | G13: =E13*F13 -> 0 | H13: =IF($C13="Kerosene",Factores!$E$6,IF($C13="Combustoleo",Factores!$E$7,IF($C13="Crudo de Castilla",Factores!$E$8,IF($C13="Avigas",Factores!$E$9,IF($C13="Jet A1",Factores!$E$10,IF($C13="Biodiesel palma",Factores!$E$11,IF($C13="Etanol Anhidro",Factores!$E$12,IF($C13="Fuel Oil # 4 - Ecopetrol",Factores!$E$13, IF($C13="Gasolina Motor",Factores!$E$14,IF($C13="Diesel Marino",Factores!$E$15,IF($C13="Diesel B2",Factores!$E$16,IF($C13="Gasolina E10 (Comercial)",Factores!$E$17,IF($C13="GLP Cartagena",Factores!$E$18,IF($C13="GLP Barrancabermeja",Factores!$E$19,IF($C13="GLP Cusiana",Factores!$E$20,IF($C13="GLP Genérico",Factores!$E$21, "0")))))))))))))))) -> 0 | I13: =(H13*G13)/1000000 -> 0 | J13: =IF($C13="Kerosene",Factores!$F$6,IF($C13="Combustoleo",Factores!$F$7,IF($C13="Crudo de Castilla",Factores!$F$8,IF($C13="Avigas",Factores!$F$9,IF($C13="Jet A1",Factores!$F$10,IF($C13="Biodiesel palma",Factores!$F$11,IF($C13="Etanol Anhidro",Factores!$F$12,IF($C13="Fuel Oil # 4 - Ecopetrol",Factores!$F$13, IF($C13="Gasolina Motor",Factores!$F$14,IF($C13="Diesel Marino",Factores!$F$15,IF($C13="Diesel B2",Factores!$F$16,IF($C13="Gasolina E10 (Comercial)",Factores!$F$17,IF($C13="GLP Cartagena",Factores!$F$18,IF($C13="GLP Barrancabermeja",Factores!$F$19,IF($C13="GLP Cusiana",Factores!$F$20,IF($C13="GLP Genérico",Factores!$F$21, "0")))))))))))))))) -> 0 | K13: =IF($C13="Kerosene",Factores!$G$6,IF($C13="Combustoleo",Factores!$G$7,IF($C13="Crudo de Castilla",Factores!$G$8,IF($C13="Avigas",Factores!$G$9,IF($C13="Jet A1",Factores!$G$10,IF($C13="Biodiesel palma",Factores!$G$11,IF($C13="Etanol Anhidro",Factores!$G$12,IF($C13="Fuel Oil # 4 - Ecopetrol",Factores!$G$13, IF($C13="Gasolina Motor",Factores!$G$14,IF($C13="Diesel Marino",Factores!$G$15,IF($C13="Diesel B2",Factores!$G$16,IF($C13="Gasolina E10 (Comercial)",Factores!$G$17,IF($C13="GLP Cartagena",Factores!$G$18,IF($C13="GLP Barrancabermeja",Factores!$G$19,IF($C13="GLP Cusiana",Factores!$G$20,IF($C13="GLP Genérico",Factores!$G$21, "0")))))))))))))))) -> 0 | L13: =IF($C13="Kerosene",Factores!$H$6,IF($C13="Combustoleo",Factores!$H$7,IF($C13="Crudo de Castilla",Factores!$H$8,IF($C13="Avigas",Factores!$H$9,IF($C13="Jet A1",Factores!$H$10,IF($C13="Biodiesel palma",Factores!$H$11,IF($C13="Etanol Anhidro",Factores!$H$12,IF($C13="Fuel Oil # 4 - Ecopetrol",Factores!$H$13, IF($C13="Gasolina Motor",Factores!$H$14,IF($C13="Diesel Marino",Factores!$H$15,IF($C13="Diesel B2",Factores!$H$16,IF($C13="Gasolina E10 (Comercial)",Factores!$H$17,IF($C13="GLP Cartagena",Factores!$H$18,IF($C13="GLP Barrancabermeja",Factores!$H$19,IF($C13="GLP Cusiana",Factores!$H$20,IF($C13="GLP Genérico",Factores!$H$21, "0")))))))))))))))) -> 0 | M13: =IF($C13="Kerosene",Factores!$J$6,IF($C13="Combustoleo",Factores!$J$7,IF($C13="Crudo de Castilla",Factores!$J$8,IF($C13="Avigas",Factores!$J$9,IF($C13="Jet A1",Factores!$J$10,IF($C13="Biodiesel palma",Factores!$J$11,IF($C13="Etanol Anhidro",Factores!$J$12,IF($C13="Fuel Oil # 4 - Ecopetrol",Factores!$J$13, IF($C13="Gasolina Motor",Factores!$J$14,IF($C13="Diesel Marino",Factores!$J$15,IF($C13="Diesel B2",Factores!$J$16,IF($C13="Gasolina E10 (Comercial)",Factores!$J$17,IF($C13="GLP Cartagena",Factores!$J$18,IF($C13="GLP Barrancabermeja",Factores!$J$19,IF($C13="GLP Cusiana",Factores!$J$20,IF($C13="GLP Genérico",Factores!$J$21, "0")))))))))))))))) -> 0 | N13: =$J13*$I13 -> 0 | O13: =$K13*$I13 -> 0 | P13: =$I13*$L13 -> 0 | Q13: =$I13*$M13 -> 0
B14: 11 | E14: =D14*3.78541 -> 0 | F14: =IF($C14="Kerosene",Factores!$D$6,IF($C14="Combustoleo",Factores!$D$7,IF($C14="Crudo de Castilla",Factores!$D$8,IF($C14="Avigas",Factores!$D$9,IF($C14="Jet A1",Factores!$D$10,IF($C14="Biodiesel palma",Factores!$D$11,IF($C14="Etanol Anhidro",Factores!$D$12,IF($C14="Fuel Oil # 4 - Ecopetrol",Factores!$D$13, IF($C14="Gasolina Motor",Factores!$D$14,IF($C14="Diesel Marino",Factores!$D$15,IF($C14="Diesel B2",Factores!$D$16,IF($C14="Gasolina E10 (Comercial)",Factores!$D$17,IF($C14="GLP Cartagena",Factores!$D$18,IF($C14="GLP Barrancabermeja",Factores!$D$19,IF($C14="GLP Cusiana",Factores!$D$20,IF($C14="GLP Genérico",Factores!$D$21, "0")))))))))))))))) -> 0 | G14: =E14*F14 -> 0 | H14: =IF($C14="Kerosene",Factores!$E$6,IF($C14="Combustoleo",Factores!$E$7,IF($C14="Crudo de Castilla",Factores!$E$8,IF($C14="Avigas",Factores!$E$9,IF($C14="Jet A1",Factores!$E$10,IF($C14="Biodiesel palma",Factores!$E$11,IF($C14="Etanol Anhidro",Factores!$E$12,IF($C14="Fuel Oil # 4 - Ecopetrol",Factores!$E$13, IF($C14="Gasolina Motor",Factores!$E$14,IF($C14="Diesel Marino",Factores!$E$15,IF($C14="Diesel B2",Factores!$E$16,IF($C14="Gasolina E10 (Comercial)",Factores!$E$17,IF($C14="GLP Cartagena",Factores!$E$18,IF($C14="GLP Barrancabermeja",Factores!$E$19,IF($C14="GLP Cusiana",Factores!$E$20,IF($C14="GLP Genérico",Factores!$E$21, "0")))))))))))))))) -> 0 | I14: =(H14*G14)/1000000 -> 0 | J14: =IF($C14="Kerosene",Factores!$F$6,IF($C14="Combustoleo",Factores!$F$7,IF($C14="Crudo de Castilla",Factores!$F$8,IF($C14="Avigas",Factores!$F$9,IF($C14="Jet A1",Factores!$F$10,IF($C14="Biodiesel palma",Factores!$F$11,IF($C14="Etanol Anhidro",Factores!$F$12,IF($C14="Fuel Oil # 4 - Ecopetrol",Factores!$F$13, IF($C14="Gasolina Motor",Factores!$F$14,IF($C14="Diesel Marino",Factores!$F$15,IF($C14="Diesel B2",Factores!$F$16,IF($C14="Gasolina E10 (Comercial)",Factores!$F$17,IF($C14="GLP Cartagena",Factores!$F$18,IF($C14="GLP Barrancabermeja",Factores!$F$19,IF($C14="GLP Cusiana",Factores!$F$20,IF($C14="GLP Genérico",Factores!$F$21, "0")))))))))))))))) -> 0 | K14: =IF($C14="Kerosene",Factores!$G$6,IF($C14="Combustoleo",Factores!$G$7,IF($C14="Crudo de Castilla",Factores!$G$8,IF($C14="Avigas",Factores!$G$9,IF($C14="Jet A1",Factores!$G$10,IF($C14="Biodiesel palma",Factores!$G$11,IF($C14="Etanol Anhidro",Factores!$G$12,IF($C14="Fuel Oil # 4 - Ecopetrol",Factores!$G$13, IF($C14="Gasolina Motor",Factores!$G$14,IF($C14="Diesel Marino",Factores!$G$15,IF($C14="Diesel B2",Factores!$G$16,IF($C14="Gasolina E10 (Comercial)",Factores!$G$17,IF($C14="GLP Cartagena",Factores!$G$18,IF($C14="GLP Barrancabermeja",Factores!$G$19,IF($C14="GLP Cusiana",Factores!$G$20,IF($C14="GLP Genérico",Factores!$G$21, "0")))))))))))))))) -> 0 | L14: =IF($C14="Kerosene",Factores!$H$6,IF($C14="Combustoleo",Factores!$H$7,IF($C14="Crudo de Castilla",Factores!$H$8,IF($C14="Avigas",Factores!$H$9,IF($C14="Jet A1",Factores!$H$10,IF($C14="Biodiesel palma",Factores!$H$11,IF($C14="Etanol Anhidro",Factores!$H$12,IF($C14="Fuel Oil # 4 - Ecopetrol",Factores!$H$13, IF($C14="Gasolina Motor",Factores!$H$14,IF($C14="Diesel Marino",Factores!$H$15,IF($C14="Diesel B2",Factores!$H$16,IF($C14="Gasolina E10 (Comercial)",Factores!$H$17,IF($C14="GLP Cartagena",Factores!$H$18,IF($C14="GLP Barrancabermeja",Factores!$H$19,IF($C14="GLP Cusiana",Factores!$H$20,IF($C14="GLP Genérico",Factores!$H$21, "0")))))))))))))))) -> 0 | M14: =IF($C14="Kerosene",Factores!$J$6,IF($C14="Combustoleo",Factores!$J$7,IF($C14="Crudo de Castilla",Factores!$J$8,IF($C14="Avigas",Factores!$J$9,IF($C14="Jet A1",Factores!$J$10,IF($C14="Biodiesel palma",Factores!$J$11,IF($C14="Etanol Anhidro",Factores!$J$12,IF($C14="Fuel Oil # 4 - Ecopetrol",Factores!$J$13, IF($C14="Gasolina Motor",Factores!$J$14,IF($C14="Diesel Marino",Factores!$J$15,IF($C14="Diesel B2",Factores!$J$16,IF($C14="Gasolina E10 (Comercial)",Factores!$J$17,IF($C14="GLP Cartagena",Factores!$J$18,IF($C14="GLP Barrancabermeja",Factores!$J$19,IF($C14="GLP Cusiana",Factores!$J$20,IF($C14="GLP Genérico",Factores!$J$21, "0")))))))))))))))) -> 0 | N14: =$J14*$I14 -> 0 | O14: =$K14*$I14 -> 0 | P14: =$I14*$L14 -> 0 | Q14: =$I14*$M14 -> 0
B15: 12 | E15: =D15*3.78541 -> 0 | F15: =IF($C15="Kerosene",Factores!$D$6,IF($C15="Combustoleo",Factores!$D$7,IF($C15="Crudo de Castilla",Factores!$D$8,IF($C15="Avigas",Factores!$D$9,IF($C15="Jet A1",Factores!$D$10,IF($C15="Biodiesel palma",Factores!$D$11,IF($C15="Etanol Anhidro",Factores!$D$12,IF($C15="Fuel Oil # 4 - Ecopetrol",Factores!$D$13, IF($C15="Gasolina Motor",Factores!$D$14,IF($C15="Diesel Marino",Factores!$D$15,IF($C15="Diesel B2",Factores!$D$16,IF($C15="Gasolina E10 (Comercial)",Factores!$D$17,IF($C15="GLP Cartagena",Factores!$D$18,IF($C15="GLP Barrancabermeja",Factores!$D$19,IF($C15="GLP Cusiana",Factores!$D$20,IF($C15="GLP Genérico",Factores!$D$21, "0")))))))))))))))) -> 0 | G15: =E15*F15 -> 0 | H15: =IF($C15="Kerosene",Factores!$E$6,IF($C15="Combustoleo",Factores!$E$7,IF($C15="Crudo de Castilla",Factores!$E$8,IF($C15="Avigas",Factores!$E$9,IF($C15="Jet A1",Factores!$E$10,IF($C15="Biodiesel palma",Factores!$E$11,IF($C15="Etanol Anhidro",Factores!$E$12,IF($C15="Fuel Oil # 4 - Ecopetrol",Factores!$E$13, IF($C15="Gasolina Motor",Factores!$E$14,IF($C15="Diesel Marino",Factores!$E$15,IF($C15="Diesel B2",Factores!$E$16,IF($C15="Gasolina E10 (Comercial)",Factores!$E$17,IF($C15="GLP Cartagena",Factores!$E$18,IF($C15="GLP Barrancabermeja",Factores!$E$19,IF($C15="GLP Cusiana",Factores!$E$20,IF($C15="GLP Genérico",Factores!$E$21, "0")))))))))))))))) -> 0 | I15: =(H15*G15)/1000000 -> 0 | J15: =IF($C15="Kerosene",Factores!$F$6,IF($C15="Combustoleo",Factores!$F$7,IF($C15="Crudo de Castilla",Factores!$F$8,IF($C15="Avigas",Factores!$F$9,IF($C15="Jet A1",Factores!$F$10,IF($C15="Biodiesel palma",Factores!$F$11,IF($C15="Etanol Anhidro",Factores!$F$12,IF($C15="Fuel Oil # 4 - Ecopetrol",Factores!$F$13, IF($C15="Gasolina Motor",Factores!$F$14,IF($C15="Diesel Marino",Factores!$F$15,IF($C15="Diesel B2",Factores!$F$16,IF($C15="Gasolina E10 (Comercial)",Factores!$F$17,IF($C15="GLP Cartagena",Factores!$F$18,IF($C15="GLP Barrancabermeja",Factores!$F$19,IF($C15="GLP Cusiana",Factores!$F$20,IF($C15="GLP Genérico",Factores!$F$21, "0")))))))))))))))) -> 0 | K15: =IF($C15="Kerosene",Factores!$G$6,IF($C15="Combustoleo",Factores!$G$7,IF($C15="Crudo de Castilla",Factores!$G$8,IF($C15="Avigas",Factores!$G$9,IF($C15="Jet A1",Factores!$G$10,IF($C15="Biodiesel palma",Factores!$G$11,IF($C15="Etanol Anhidro",Factores!$G$12,IF($C15="Fuel Oil # 4 - Ecopetrol",Factores!$G$13, IF($C15="Gasolina Motor",Factores!$G$14,IF($C15="Diesel Marino",Factores!$G$15,IF($C15="Diesel B2",Factores!$G$16,IF($C15="Gasolina E10 (Comercial)",Factores!$G$17,IF($C15="GLP Cartagena",Factores!$G$18,IF($C15="GLP Barrancabermeja",Factores!$G$19,IF($C15="GLP Cusiana",Factores!$G$20,IF($C15="GLP Genérico",Factores!$G$21, "0")))))))))))))))) -> 0 | L15: =IF($C15="Kerosene",Factores!$H$6,IF($C15="Combustoleo",Factores!$H$7,IF($C15="Crudo de Castilla",Factores!$H$8,IF($C15="Avigas",Factores!$H$9,IF($C15="Jet A1",Factores!$H$10,IF($C15="Biodiesel palma",Factores!$H$11,IF($C15="Etanol Anhidro",Factores!$H$12,IF($C15="Fuel Oil # 4 - Ecopetrol",Factores!$H$13, IF($C15="Gasolina Motor",Factores!$H$14,IF($C15="Diesel Marino",Factores!$H$15,IF($C15="Diesel B2",Factores!$H$16,IF($C15="Gasolina E10 (Comercial)",Factores!$H$17,IF($C15="GLP Cartagena",Factores!$H$18,IF($C15="GLP Barrancabermeja",Factores!$H$19,IF($C15="GLP Cusiana",Factores!$H$20,IF($C15="GLP Genérico",Factores!$H$21, "0")))))))))))))))) -> 0 | M15: =IF($C15="Kerosene",Factores!$J$6,IF($C15="Combustoleo",Factores!$J$7,IF($C15="Crudo de Castilla",Factores!$J$8,IF($C15="Avigas",Factores!$J$9,IF($C15="Jet A1",Factores!$J$10,IF($C15="Biodiesel palma",Factores!$J$11,IF($C15="Etanol Anhidro",Factores!$J$12,IF($C15="Fuel Oil # 4 - Ecopetrol",Factores!$J$13, IF($C15="Gasolina Motor",Factores!$J$14,IF($C15="Diesel Marino",Factores!$J$15,IF($C15="Diesel B2",Factores!$J$16,IF($C15="Gasolina E10 (Comercial)",Factores!$J$17,IF($C15="GLP Cartagena",Factores!$J$18,IF($C15="GLP Barrancabermeja",Factores!$J$19,IF($C15="GLP Cusiana",Factores!$J$20,IF($C15="GLP Genérico",Factores!$J$21, "0")))))))))))))))) -> 0 | N15: =$J15*$I15 -> 0 | O15: =$K15*$I15 -> 0 | P15: =$I15*$L15 -> 0 | Q15: =$I15*$M15 -> 0
B16: 13 | E16: =D16*3.78541 -> 0 | F16: =IF($C16="Kerosene",Factores!$D$6,IF($C16="Combustoleo",Factores!$D$7,IF($C16="Crudo de Castilla",Factores!$D$8,IF($C16="Avigas",Factores!$D$9,IF($C16="Jet A1",Factores!$D$10,IF($C16="Biodiesel palma",Factores!$D$11,IF($C16="Etanol Anhidro",Factores!$D$12,IF($C16="Fuel Oil # 4 - Ecopetrol",Factores!$D$13, IF($C16="Gasolina Motor",Factores!$D$14,IF($C16="Diesel Marino",Factores!$D$15,IF($C16="Diesel B2",Factores!$D$16,IF($C16="Gasolina E10 (Comercial)",Factores!$D$17,IF($C16="GLP Cartagena",Factores!$D$18,IF($C16="GLP Barrancabermeja",Factores!$D$19,IF($C16="GLP Cusiana",Factores!$D$20,IF($C16="GLP Genérico",Factores!$D$21, "0")))))))))))))))) -> 0 | G16: =E16*F16 -> 0 | H16: =IF($C16="Kerosene",Factores!$E$6,IF($C16="Combustoleo",Factores!$E$7,IF($C16="Crudo de Castilla",Factores!$E$8,IF($C16="Avigas",Factores!$E$9,IF($C16="Jet A1",Factores!$E$10,IF($C16="Biodiesel palma",Factores!$E$11,IF($C16="Etanol Anhidro",Factores!$E$12,IF($C16="Fuel Oil # 4 - Ecopetrol",Factores!$E$13, IF($C16="Gasolina Motor",Factores!$E$14,IF($C16="Diesel Marino",Factores!$E$15,IF($C16="Diesel B2",Factores!$E$16,IF($C16="Gasolina E10 (Comercial)",Factores!$E$17,IF($C16="GLP Cartagena",Factores!$E$18,IF($C16="GLP Barrancabermeja",Factores!$E$19,IF($C16="GLP Cusiana",Factores!$E$20,IF($C16="GLP Genérico",Factores!$E$21, "0")))))))))))))))) -> 0 | I16: =(H16*G16)/1000000 -> 0 | J16: =IF($C16="Kerosene",Factores!$F$6,IF($C16="Combustoleo",Factores!$F$7,IF($C16="Crudo de Castilla",Factores!$F$8,IF($C16="Avigas",Factores!$F$9,IF($C16="Jet A1",Factores!$F$10,IF($C16="Biodiesel palma",Factores!$F$11,IF($C16="Etanol Anhidro",Factores!$F$12,IF($C16="Fuel Oil # 4 - Ecopetrol",Factores!$F$13, IF($C16="Gasolina Motor",Factores!$F$14,IF($C16="Diesel Marino",Factores!$F$15,IF($C16="Diesel B2",Factores!$F$16,IF($C16="Gasolina E10 (Comercial)",Factores!$F$17,IF($C16="GLP Cartagena",Factores!$F$18,IF($C16="GLP Barrancabermeja",Factores!$F$19,IF($C16="GLP Cusiana",Factores!$F$20,IF($C16="GLP Genérico",Factores!$F$21, "0")))))))))))))))) -> 0 | K16: =IF($C16="Kerosene",Factores!$G$6,IF($C16="Combustoleo",Factores!$G$7,IF($C16="Crudo de Castilla",Factores!$G$8,IF($C16="Avigas",Factores!$G$9,IF($C16="Jet A1",Factores!$G$10,IF($C16="Biodiesel palma",Factores!$G$11,IF($C16="Etanol Anhidro",Factores!$G$12,IF($C16="Fuel Oil # 4 - Ecopetrol",Factores!$G$13, IF($C16="Gasolina Motor",Factores!$G$14,IF($C16="Diesel Marino",Factores!$G$15,IF($C16="Diesel B2",Factores!$G$16,IF($C16="Gasolina E10 (Comercial)",Factores!$G$17,IF($C16="GLP Cartagena",Factores!$G$18,IF($C16="GLP Barrancabermeja",Factores!$G$19,IF($C16="GLP Cusiana",Factores!$G$20,IF($C16="GLP Genérico",Factores!$G$21, "0")))))))))))))))) -> 0 | L16: =IF($C16="Kerosene",Factores!$H$6,IF($C16="Combustoleo",Factores!$H$7,IF($C16="Crudo de Castilla",Factores!$H$8,IF($C16="Avigas",Factores!$H$9,IF($C16="Jet A1",Factores!$H$10,IF($C16="Biodiesel palma",Factores!$H$11,IF($C16="Etanol Anhidro",Factores!$H$12,IF($C16="Fuel Oil # 4 - Ecopetrol",Factores!$H$13, IF($C16="Gasolina Motor",Factores!$H$14,IF($C16="Diesel Marino",Factores!$H$15,IF($C16="Diesel B2",Factores!$H$16,IF($C16="Gasolina E10 (Comercial)",Factores!$H$17,IF($C16="GLP Cartagena",Factores!$H$18,IF($C16="GLP Barrancabermeja",Factores!$H$19,IF($C16="GLP Cusiana",Factores!$H$20,IF($C16="GLP Genérico",Factores!$H$21, "0")))))))))))))))) -> 0 | M16: =IF($C16="Kerosene",Factores!$J$6,IF($C16="Combustoleo",Factores!$J$7,IF($C16="Crudo de Castilla",Factores!$J$8,IF($C16="Avigas",Factores!$J$9,IF($C16="Jet A1",Factores!$J$10,IF($C16="Biodiesel palma",Factores!$J$11,IF($C16="Etanol Anhidro",Factores!$J$12,IF($C16="Fuel Oil # 4 - Ecopetrol",Factores!$J$13, IF($C16="Gasolina Motor",Factores!$J$14,IF($C16="Diesel Marino",Factores!$J$15,IF($C16="Diesel B2",Factores!$J$16,IF($C16="Gasolina E10 (Comercial)",Factores!$J$17,IF($C16="GLP Cartagena",Factores!$J$18,IF($C16="GLP Barrancabermeja",Factores!$J$19,IF($C16="GLP Cusiana",Factores!$J$20,IF($C16="GLP Genérico",Factores!$J$21, "0")))))))))))))))) -> 0 | N16: =$J16*$I16 -> 0 | O16: =$K16*$I16 -> 0 | P16: =$I16*$L16 -> 0 | Q16: =$I16*$M16 -> 0
B17: 14 | E17: =D17*3.78541 -> 0 | F17: =IF($C17="Kerosene",Factores!$D$6,IF($C17="Combustoleo",Factores!$D$7,IF($C17="Crudo de Castilla",Factores!$D$8,IF($C17="Avigas",Factores!$D$9,IF($C17="Jet A1",Factores!$D$10,IF($C17="Biodiesel palma",Factores!$D$11,IF($C17="Etanol Anhidro",Factores!$D$12,IF($C17="Fuel Oil # 4 - Ecopetrol",Factores!$D$13, IF($C17="Gasolina Motor",Factores!$D$14,IF($C17="Diesel Marino",Factores!$D$15,IF($C17="Diesel B2",Factores!$D$16,IF($C17="Gasolina E10 (Comercial)",Factores!$D$17,IF($C17="GLP Cartagena",Factores!$D$18,IF($C17="GLP Barrancabermeja",Factores!$D$19,IF($C17="GLP Cusiana",Factores!$D$20,IF($C17="GLP Genérico",Factores!$D$21, "0")))))))))))))))) -> 0 | G17: =E17*F17 -> 0 | H17: =IF($C17="Kerosene",Factores!$E$6,IF($C17="Combustoleo",Factores!$E$7,IF($C17="Crudo de Castilla",Factores!$E$8,IF($C17="Avigas",Factores!$E$9,IF($C17="Jet A1",Factores!$E$10,IF($C17="Biodiesel palma",Factores!$E$11,IF($C17="Etanol Anhidro",Factores!$E$12,IF($C17="Fuel Oil # 4 - Ecopetrol",Factores!$E$13, IF($C17="Gasolina Motor",Factores!$E$14,IF($C17="Diesel Marino",Factores!$E$15,IF($C17="Diesel B2",Factores!$E$16,IF($C17="Gasolina E10 (Comercial)",Factores!$E$17,IF($C17="GLP Cartagena",Factores!$E$18,IF($C17="GLP Barrancabermeja",Factores!$E$19,IF($C17="GLP Cusiana",Factores!$E$20,IF($C17="GLP Genérico",Factores!$E$21, "0")))))))))))))))) -> 0 | I17: =(H17*G17)/1000000 -> 0 | J17: =IF($C17="Kerosene",Factores!$F$6,IF($C17="Combustoleo",Factores!$F$7,IF($C17="Crudo de Castilla",Factores!$F$8,IF($C17="Avigas",Factores!$F$9,IF($C17="Jet A1",Factores!$F$10,IF($C17="Biodiesel palma",Factores!$F$11,IF($C17="Etanol Anhidro",Factores!$F$12,IF($C17="Fuel Oil # 4 - Ecopetrol",Factores!$F$13, IF($C17="Gasolina Motor",Factores!$F$14,IF($C17="Diesel Marino",Factores!$F$15,IF($C17="Diesel B2",Factores!$F$16,IF($C17="Gasolina E10 (Comercial)",Factores!$F$17,IF($C17="GLP Cartagena",Factores!$F$18,IF($C17="GLP Barrancabermeja",Factores!$F$19,IF($C17="GLP Cusiana",Factores!$F$20,IF($C17="GLP Genérico",Factores!$F$21, "0")))))))))))))))) -> 0 | K17: =IF($C17="Kerosene",Factores!$G$6,IF($C17="Combustoleo",Factores!$G$7,IF($C17="Crudo de Castilla",Factores!$G$8,IF($C17="Avigas",Factores!$G$9,IF($C17="Jet A1",Factores!$G$10,IF($C17="Biodiesel palma",Factores!$G$11,IF($C17="Etanol Anhidro",Factores!$G$12,IF($C17="Fuel Oil # 4 - Ecopetrol",Factores!$G$13, IF($C17="Gasolina Motor",Factores!$G$14,IF($C17="Diesel Marino",Factores!$G$15,IF($C17="Diesel B2",Factores!$G$16,IF($C17="Gasolina E10 (Comercial)",Factores!$G$17,IF($C17="GLP Cartagena",Factores!$G$18,IF($C17="GLP Barrancabermeja",Factores!$G$19,IF($C17="GLP Cusiana",Factores!$G$20,IF($C17="GLP Genérico",Factores!$G$21, "0")))))))))))))))) -> 0 | L17: =IF($C17="Kerosene",Factores!$H$6,IF($C17="Combustoleo",Factores!$H$7,IF($C17="Crudo de Castilla",Factores!$H$8,IF($C17="Avigas",Factores!$H$9,IF($C17="Jet A1",Factores!$H$10,IF($C17="Biodiesel palma",Factores!$H$11,IF($C17="Etanol Anhidro",Factores!$H$12,IF($C17="Fuel Oil # 4 - Ecopetrol",Factores!$H$13, IF($C17="Gasolina Motor",Factores!$H$14,IF($C17="Diesel Marino",Factores!$H$15,IF($C17="Diesel B2",Factores!$H$16,IF($C17="Gasolina E10 (Comercial)",Factores!$H$17,IF($C17="GLP Cartagena",Factores!$H$18,IF($C17="GLP Barrancabermeja",Factores!$H$19,IF($C17="GLP Cusiana",Factores!$H$20,IF($C17="GLP Genérico",Factores!$H$21, "0")))))))))))))))) -> 0 | M17: =IF($C17="Kerosene",Factores!$J$6,IF($C17="Combustoleo",Factores!$J$7,IF($C17="Crudo de Castilla",Factores!$J$8,IF($C17="Avigas",Factores!$J$9,IF($C17="Jet A1",Factores!$J$10,IF($C17="Biodiesel palma",Factores!$J$11,IF($C17="Etanol Anhidro",Factores!$J$12,IF($C17="Fuel Oil # 4 - Ecopetrol",Factores!$J$13, IF($C17="Gasolina Motor",Factores!$J$14,IF($C17="Diesel Marino",Factores!$J$15,IF($C17="Diesel B2",Factores!$J$16,IF($C17="Gasolina E10 (Comercial)",Factores!$J$17,IF($C17="GLP Cartagena",Factores!$J$18,IF($C17="GLP Barrancabermeja",Factores!$J$19,IF($C17="GLP Cusiana",Factores!$J$20,IF($C17="GLP Genérico",Factores!$J$21, "0")))))))))))))))) -> 0 | N17: =$J17*$I17 -> 0 | O17: =$K17*$I17 -> 0 | P17: =$I17*$L17 -> 0 | Q17: =$I17*$M17 -> 0
B18: 15 | E18: =D18*3.78541 -> 0 | F18: =IF($C18="Kerosene",Factores!$D$6,IF($C18="Combustoleo",Factores!$D$7,IF($C18="Crudo de Castilla",Factores!$D$8,IF($C18="Avigas",Factores!$D$9,IF($C18="Jet A1",Factores!$D$10,IF($C18="Biodiesel palma",Factores!$D$11,IF($C18="Etanol Anhidro",Factores!$D$12,IF($C18="Fuel Oil # 4 - Ecopetrol",Factores!$D$13, IF($C18="Gasolina Motor",Factores!$D$14,IF($C18="Diesel Marino",Factores!$D$15,IF($C18="Diesel B2",Factores!$D$16,IF($C18="Gasolina E10 (Comercial)",Factores!$D$17,IF($C18="GLP Cartagena",Factores!$D$18,IF($C18="GLP Barrancabermeja",Factores!$D$19,IF($C18="GLP Cusiana",Factores!$D$20,IF($C18="GLP Genérico",Factores!$D$21, "0")))))))))))))))) -> 0 | G18: =E18*F18 -> 0 | H18: =IF($C18="Kerosene",Factores!$E$6,IF($C18="Combustoleo",Factores!$E$7,IF($C18="Crudo de Castilla",Factores!$E$8,IF($C18="Avigas",Factores!$E$9,IF($C18="Jet A1",Factores!$E$10,IF($C18="Biodiesel palma",Factores!$E$11,IF($C18="Etanol Anhidro",Factores!$E$12,IF($C18="Fuel Oil # 4 - Ecopetrol",Factores!$E$13, IF($C18="Gasolina Motor",Factores!$E$14,IF($C18="Diesel Marino",Factores!$E$15,IF($C18="Diesel B2",Factores!$E$16,IF($C18="Gasolina E10 (Comercial)",Factores!$E$17,IF($C18="GLP Cartagena",Factores!$E$18,IF($C18="GLP Barrancabermeja",Factores!$E$19,IF($C18="GLP Cusiana",Factores!$E$20,IF($C18="GLP Genérico",Factores!$E$21, "0")))))))))))))))) -> 0 | I18: =(H18*G18)/1000000 -> 0 | J18: =IF($C18="Kerosene",Factores!$F$6,IF($C18="Combustoleo",Factores!$F$7,IF($C18="Crudo de Castilla",Factores!$F$8,IF($C18="Avigas",Factores!$F$9,IF($C18="Jet A1",Factores!$F$10,IF($C18="Biodiesel palma",Factores!$F$11,IF($C18="Etanol Anhidro",Factores!$F$12,IF($C18="Fuel Oil # 4 - Ecopetrol",Factores!$F$13, IF($C18="Gasolina Motor",Factores!$F$14,IF($C18="Diesel Marino",Factores!$F$15,IF($C18="Diesel B2",Factores!$F$16,IF($C18="Gasolina E10 (Comercial)",Factores!$F$17,IF($C18="GLP Cartagena",Factores!$F$18,IF($C18="GLP Barrancabermeja",Factores!$F$19,IF($C18="GLP Cusiana",Factores!$F$20,IF($C18="GLP Genérico",Factores!$F$21, "0")))))))))))))))) -> 0 | K18: =IF($C18="Kerosene",Factores!$G$6,IF($C18="Combustoleo",Factores!$G$7,IF($C18="Crudo de Castilla",Factores!$G$8,IF($C18="Avigas",Factores!$G$9,IF($C18="Jet A1",Factores!$G$10,IF($C18="Biodiesel palma",Factores!$G$11,IF($C18="Etanol Anhidro",Factores!$G$12,IF($C18="Fuel Oil # 4 - Ecopetrol",Factores!$G$13, IF($C18="Gasolina Motor",Factores!$G$14,IF($C18="Diesel Marino",Factores!$G$15,IF($C18="Diesel B2",Factores!$G$16,IF($C18="Gasolina E10 (Comercial)",Factores!$G$17,IF($C18="GLP Cartagena",Factores!$G$18,IF($C18="GLP Barrancabermeja",Factores!$G$19,IF($C18="GLP Cusiana",Factores!$G$20,IF($C18="GLP Genérico",Factores!$G$21, "0")))))))))))))))) -> 0 | L18: =IF($C18="Kerosene",Factores!$H$6,IF($C18="Combustoleo",Factores!$H$7,IF($C18="Crudo de Castilla",Factores!$H$8,IF($C18="Avigas",Factores!$H$9,IF($C18="Jet A1",Factores!$H$10,IF($C18="Biodiesel palma",Factores!$H$11,IF($C18="Etanol Anhidro",Factores!$H$12,IF($C18="Fuel Oil # 4 - Ecopetrol",Factores!$H$13, IF($C18="Gasolina Motor",Factores!$H$14,IF($C18="Diesel Marino",Factores!$H$15,IF($C18="Diesel B2",Factores!$H$16,IF($C18="Gasolina E10 (Comercial)",Factores!$H$17,IF($C18="GLP Cartagena",Factores!$H$18,IF($C18="GLP Barrancabermeja",Factores!$H$19,IF($C18="GLP Cusiana",Factores!$H$20,IF($C18="GLP Genérico",Factores!$H$21, "0")))))))))))))))) -> 0 | M18: =IF($C18="Kerosene",Factores!$J$6,IF($C18="Combustoleo",Factores!$J$7,IF($C18="Crudo de Castilla",Factores!$J$8,IF($C18="Avigas",Factores!$J$9,IF($C18="Jet A1",Factores!$J$10,IF($C18="Biodiesel palma",Factores!$J$11,IF($C18="Etanol Anhidro",Factores!$J$12,IF($C18="Fuel Oil # 4 - Ecopetrol",Factores!$J$13, IF($C18="Gasolina Motor",Factores!$J$14,IF($C18="Diesel Marino",Factores!$J$15,IF($C18="Diesel B2",Factores!$J$16,IF($C18="Gasolina E10 (Comercial)",Factores!$J$17,IF($C18="GLP Cartagena",Factores!$J$18,IF($C18="GLP Barrancabermeja",Factores!$J$19,IF($C18="GLP Cusiana",Factores!$J$20,IF($C18="GLP Genérico",Factores!$J$21, "0")))))))))))))))) -> 0 | N18: =$J18*$I18 -> 0 | O18: =$K18*$I18 -> 0 | P18: =$I18*$L18 -> 0 | Q18: =$I18*$M18 -> 0
